Workbook

Sheet Data
A1: MUNICIPALITY | E1: VISIT DATA | I1: RESTAURANT LINK | K1: WIKIPEDIA | L1: INSTAGRAM | P1: TIKTOK | T1: YOUTUBE | X1: THREADS | AB1: BLUESKY | AF1: FACEBOOK | AJ1: EXTRA / OVERFLOW LINKS
A2: name | B2: county | C2: geoid | D2: townType | E2: status | F2: visitNumber | G2: restaurantName | H2: dateVisited | I2: restaurant_label | J2: restaurant_url | K2: wikipedia_url | L2: instagram1_label | M2: instagram1_url | N2: instagram2_label | O2: instagram2_url | P2: tiktok1_label | Q2: tiktok1_url | R2: tiktok2_label | S2: tiktok2_url | T2: youtube1_label | U2: youtube1_url | V2: youtube2_label | W2: youtube2_url | X2: threads1_label | Y2: threads1_url | Z2: threads2_label | AA2: threads2_url | AB2: bluesky1_label | AC2: bluesky1_url | AD2: bluesky2_label | AE2: bluesky2_url | AF2: facebook1_label | AG2: facebook1_url | AH2: facebook2_label | AI2: facebook2_url | AJ2: extra1_category | AK2: extra1_platform | AL2: extra1_label | AM2: extra1_url | AN2: extra2_category | AO2: extra2_platform | AP2: extra2_label | AQ2: extra2_url | AR2: extra3_category | AS2: extra3_platform | AT2: extra3_label | AU2: extra3_url
A3: Aberdeen | B3: Monmouth | C3: 3402500070 | D3: township | E3: pre-challenge | G3: Alternate Ending | H3: 45042 | I3: Alternate Ending Beer Co. | J3: https://www.alternateendingbeerco.com/ | K3: =IF(A3="","","https://en.wikipedia.org/wiki/"&SUBSTITUTE(A3," ","_")&IF(D3="township","_Township","")&",_New_Jersey") -> https://en.wikipedia.org/wiki/Aberdeen_Township,_New_Jersey
A4: Absecon | B4: Atlantic | C4: 3400100100 | D4: city | E4: unvisited | K4: =IF(A4="","","https://en.wikipedia.org/wiki/"&SUBSTITUTE(A4," ","_")&IF(D4="township","_Township","")&",_New_Jersey") -> https://en.wikipedia.org/wiki/Absecon,_New_Jersey
A5: Alexandria | B5: Hunterdon | C5: 3401900550 | D5: township | E5: queued | F5: 245 | G5: The Ciderhouse At Ironbound Farm | H5: 45599 | I5: Ironbound Farm and Ciderhouse | J5: https://www.ironboundhardcider.com/ | K5: =IF(A5="","","https://en.wikipedia.org/wiki/"&SUBSTITUTE(A5," ","_")&IF(D5="township","_Township","")&",_New_Jersey") -> https://en.wikipedia.org/wiki/Alexandria_Township,_New_Jersey
A6: Allamuchy | B6: Warren | C6: 3404100670 | D6: township | E6: unvisited | K6: =IF(A6="","","https://en.wikipedia.org/wiki/"&SUBSTITUTE(A6," ","_")&IF(D6="township","_Township","")&",_New_Jersey") -> https://en.wikipedia.org/wiki/Allamuchy_Township,_New_Jersey
A7: Allendale | B7: Bergen | C7: 3400300700 | D7: borough | E7: unvisited | K7: =IF(A7="","","https://en.wikipedia.org/wiki/"&SUBSTITUTE(A7," ","_")&IF(D7="township","_Township","")&",_New_Jersey") -> https://en.wikipedia.org/wiki/Allendale,_New_Jersey
A8: Allenhurst | B8: Monmouth | C8: 3402500730 | D8: borough | E8: visited | F8: 91 | G8: Mister C's | H8: 45122 | I8: Mister C's Beach Bistro | J8: http://www.mistercsbeachbistro.com/ | K8: =IF(A8="","","https://en.wikipedia.org/wiki/"&SUBSTITUTE(A8," ","_")&IF(D8="township","_Township","")&",_New_Jersey") -> https://en.wikipedia.org/wiki/Allenhurst,_New_Jersey | L8: NJ Town #91: Allenhurst | M8: https://www.instagram.com/p/DDk5FqqxJAT/ | AL8: Town #91 | AM8: https://www.instagram.com/p/DDk5FqqxJAT/?img_index=1
A9: Allentown | B9: Monmouth | C9: 3402500760 | D9: borough | E9: visited | F9: 96 | G9: Woody's Towne Café | H9: 45143 | I9: Woody's Towne Cafe | K9: =IF(A9="","","https://en.wikipedia.org/wiki/"&SUBSTITUTE(A9," ","_")&IF(D9="township","_Township","")&",_New_Jersey") -> https://en.wikipedia.org/wiki/Allentown,_New_Jersey | L9: NJ Town #96: Allentown | M9: https://www.instagram.com/p/DEnQVmrxshl/ | AL9: Town #96 | AM9: https://www.instagram.com/p/DEnQVmrxshl/
A10: Alloway | B10: Salem | C10: 3403300880 | D10: township | E10: unvisited | K10: =IF(A10="","","https://en.wikipedia.org/wiki/"&SUBSTITUTE(A10," ","_")&IF(D10="township","_Township","")&",_New_Jersey") -> https://en.wikipedia.org/wiki/Alloway_Township,_New_Jersey
A11: Alpha | B11: Warren | C11: 3404101030 | D11: borough | E11: queued | F11: 140 | G11: Alpha Family Restaurant | H11: 45248 | I11: Alpha Family Restaurant | K11: =IF(A11="","","https://en.wikipedia.org/wiki/"&SUBSTITUTE(A11," ","_")&IF(D11="township","_Township","")&",_New_Jersey") -> https://en.wikipedia.org/wiki/Alpha,_New_Jersey
A12: Alpine | B12: Bergen | C12: 3400301090 | D12: borough | E12: queued | F12: 239 | G12: Kiku Japanese Steakhouse | H12: 2024-10-11 | I12: Kiku Japanese Steakhouse | J12: https://www.kikurestaurantsnj.com/ | K12: =IF(A12="","","https://en.wikipedia.org/wiki/"&SUBSTITUTE(A12," ","_")&IF(D12="township","_Township","")&",_New_Jersey") -> https://en.wikipedia.org/wiki/Alpine,_New_Jersey
A13: Andover | B13: Sussex | C13: 3403701330 | D13: borough | E13: unvisited | K13: =IF(A13="","","https://en.wikipedia.org/wiki/"&SUBSTITUTE(A13," ","_")&IF(D13="township","_Township","")&",_New_Jersey") -> https://en.wikipedia.org/wiki/Andover,_New_Jersey
A14: Andover | B14: Sussex | C14: 3403701360 | D14: township | E14: unvisited | K14: =IF(A14="","","https://en.wikipedia.org/wiki/"&SUBSTITUTE(A14," ","_")&IF(D14="township","_Township","")&",_New_Jersey") -> https://en.wikipedia.org/wiki/Andover_Township,_New_Jersey
A15: Asbury Park | B15: Monmouth | C15: 3402501960 | D15: city | E15: pre-challenge | G15: Pascal & Sabine | H15: 44970 | I15: Pascal & Sabine | J15: https://www.pascalandsabine.com/ | K15: =IF(A15="","","https://en.wikipedia.org/wiki/"&SUBSTITUTE(A15," ","_")&IF(D15="township","_Township","")&",_New_Jersey") -> https://en.wikipedia.org/wiki/Asbury_Park,_New_Jersey
A16: Atlantic City | B16: Atlantic | C16: 3400102080 | D16: city | E16: pre-challenge | G16: Amada | H16: 43639 | I16: Amada | J16: https://www.theoceanac.com/restaurants/amada | K16: =IF(A16="","","https://en.wikipedia.org/wiki/"&SUBSTITUTE(A16," ","_")&IF(D16="township","_Township","")&",_New_Jersey") -> https://en.wikipedia.org/wiki/Atlantic_City,_New_Jersey
A17: Atlantic Highlands | B17: Monmouth | C17: 3402502110 | D17: borough | E17: visited | F17: 89 | G17: On The Deck | H17: 45121 | I17: On The Deck | J17: https://www.onthedeckrestaurant.com/ | K17: =IF(A17="","","https://en.wikipedia.org/wiki/"&SUBSTITUTE(A17," ","_")&IF(D17="township","_Township","")&",_New_Jersey") -> https://en.wikipedia.org/wiki/Atlantic_Highlands,_New_Jersey | L17: NJ Town #89: Atlantic Highlands | M17: https://www.instagram.com/p/DDV4lsBxiYH/ | AL17: Town #89 | AM17: https://www.instagram.com/p/DDV4lsBxiYH/
A18: Audubon | B18: Camden | C18: 3400702200 | D18: borough | E18: queued | F18: 283 | G18: Cafe Nitido | H18: 2025-12-31 | I18: Café Nitido | K18: =IF(A18="","","https://en.wikipedia.org/wiki/"&SUBSTITUTE(A18," ","_")&IF(D18="township","_Township","")&",_New_Jersey") -> https://en.wikipedia.org/wiki/Audubon,_New_Jersey
A19: Audubon Park | B19: Camden | C19: 3400702230 | D19: borough | E19: unvisited | K19: =IF(A19="","","https://en.wikipedia.org/wiki/"&SUBSTITUTE(A19," ","_")&IF(D19="township","_Township","")&",_New_Jersey") -> https://en.wikipedia.org/wiki/Audubon_Park,_New_Jersey
A20: Avalon | B20: Cape May | C20: 3400902320 | D20: borough | E20: unvisited | K20: =IF(A20="","","https://en.wikipedia.org/wiki/"&SUBSTITUTE(A20," ","_")&IF(D20="township","_Township","")&",_New_Jersey") -> https://en.wikipedia.org/wiki/Avalon,_New_Jersey
A21: Avon-by-the-Sea | B21: Monmouth | C21: 3402502440 | D21: borough | E21: visited | F21: 104 | G21: The Columns | H21: 45156 | I21: The Columns | J21: https://thecolumnsnj.com/ | K21: =IF(A21="","","https://en.wikipedia.org/wiki/"&SUBSTITUTE(A21," ","_")&IF(D21="township","_Township","")&",_New_Jersey") -> https://en.wikipedia.org/wiki/Avon-by-the-Sea,_New_Jersey | L21: NJ Town #104: Avon-by-the-Sea | M21: https://www.instagram.com/p/DF0YLZfxU-q/ | AL21: Town #104 | AM21: https://www.instagram.com/p/DF0YLZfxU-q/
A22: Barnegat | B22: Ocean | C22: 3402903050 | D22: township | E22: queued | F22: 227 | G22: Sun Harbor Seafood & Grill | H22: 45535 | I22: Sun Harbor Seafood and Grill | J22: https://www.sunharborseafoodandgrill.com/ | K22: =IF(A22="","","https://en.wikipedia.org/wiki/"&SUBSTITUTE(A22," ","_")&IF(D22="township","_Township","")&",_New_Jersey") -> https://en.wikipedia.org/wiki/Barnegat_Township,_New_Jersey
A23: Barnegat Light | B23: Ocean | C23: 3402903130 | D23: borough | E23: queued | F23: 218 | G23: Mustache Bill's Diner | H23: 45515 | I23: Mustache Bill's Diner | J23: https://mustachebills.com/ | K23: =IF(A23="","","https://en.wikipedia.org/wiki/"&SUBSTITUTE(A23," ","_")&IF(D23="township","_Township","")&",_New_Jersey") -> https://en.wikipedia.org/wiki/Barnegat_Light,_New_Jersey
A24: Barrington | B24: Camden | C24: 3400703250 | D24: borough | E24: queued | F24: 275 | G24: Old Rail Bar | H24: 2025-06-16 | I24: Old Rail Tavern | J24: https://theoldrailtavern.com/ | K24: =IF(A24="","","https://en.wikipedia.org/wiki/"&SUBSTITUTE(A24," ","_")&IF(D24="township","_Township","")&",_New_Jersey") -> https://en.wikipedia.org/wiki/Barrington,_New_Jersey
A25: Bass River | B25: Burlington | C25: 3400503370 | D25: township | E25: queued | F25: 224 | G25: Sad Boyz | H25: 45529 | I25: Sad Boyz | J25: https://sadboyzbites.com/ | K25: =IF(A25="","","https://en.wikipedia.org/wiki/"&SUBSTITUTE(A25," ","_")&IF(D25="township","_Township","")&",_New_Jersey") -> https://en.wikipedia.org/wiki/Bass_River_Township,_New_Jersey
A26: Bay Head | B26: Ocean | C26: 3402903520 | D26: borough | E26: queued | F26: 232 | G26: The Grenville Restaurant & Hotel | H26: 45554 | I26: The Grenville Hotel & Restaurant | J26: https://www.thegrenville.com/ | K26: =IF(A26="","","https://en.wikipedia.org/wiki/"&SUBSTITUTE(A26," ","_")&IF(D26="township","_Township","")&",_New_Jersey") -> https://en.wikipedia.org/wiki/Bay_Head,_New_Jersey
A27: Bayonne | B27: Hudson | C27: 3401703580 | D27: city | E27: pre-challenge | G27: Otaiko Hibachi & Sushi Lounge | H27: 44746 | I27: Otaiko Hibachi & Sushi Lounge | J27: https://otaikobayonne.com/ | K27: =IF(A27="","","https://en.wikipedia.org/wiki/"&SUBSTITUTE(A27," ","_")&IF(D27="township","_Township","")&",_New_Jersey") -> https://en.wikipedia.org/wiki/Bayonne,_New_Jersey
A28: Beach Haven | B28: Ocean | C28: 3402903940 | D28: borough | E28: queued | F28: 193 | G28: Black Whale Bar & Fish House | H28: 45416 | I28: Black Whale Bar & Fish House | J28: https://www.blackwhalebar.com/ | K28: =IF(A28="","","https://en.wikipedia.org/wiki/"&SUBSTITUTE(A28," ","_")&IF(D28="township","_Township","")&",_New_Jersey") -> https://en.wikipedia.org/wiki/Beach_Haven,_New_Jersey
A29: Beachwood | B29: Ocean | C29: 3402904180 | D29: borough | E29: visited | F29: 124 | G29: Sand Castle Diner | H29: 45214 | I29: Sand Castle Diner | J29: https://sandcastledinernj.com/ | K29: =IF(A29="","","https://en.wikipedia.org/wiki/"&SUBSTITUTE(A29," ","_")&IF(D29="township","_Township","")&",_New_Jersey") -> https://en.wikipedia.org/wiki/Beachwood,_New_Jersey | L29: NJ Town #124: Beachwood | M29: https://www.instagram.com/p/DRXTcRNEbbt/ | N29: NJ Town #124: Bonus Town Trivia | O29: https://www.instagram.com/p/DRpKS1OES5O/?img_index=1 | AF29: NJ Town #124: Beachwood | AG29: https://www.facebook.com/reel/1543556009974817 | AH29: NJ Town #124: Bonus Town Trivia | AI29: https://www.facebook.com/permalink.php?story_fbid=pfbid04dYD4JWGLk55bhtpT3ZBfwCubZPaQ6vyAMKrpzzZ6tjHvnetXEDh4RXSxpeLbb1bl&id=61569640546791 | AL29: Town #124 | AM29: https://www.instagram.com/p/DRXTcRNEbbt/ | AP29: Town #124 - Bonus Town Trivia | AQ29: https://www.instagram.com/p/DRpKS1OES5O/?img_index=1
A30: Bedminster | B30: Somerset | C30: 3403504450 | D30: township | E30: unvisited | K30: =IF(A30="","","https://en.wikipedia.org/wiki/"&SUBSTITUTE(A30," ","_")&IF(D30="township","_Township","")&",_New_Jersey") -> https://en.wikipedia.org/wiki/Bedminster_Township,_New_Jersey
A31: Belleville | B31: Essex | C31: 3401304695 | D31: township | E31: unvisited | K31: =IF(A31="","","https://en.wikipedia.org/wiki/"&SUBSTITUTE(A31," ","_")&IF(D31="township","_Township","")&",_New_Jersey") -> https://en.wikipedia.org/wiki/Belleville_Township,_New_Jersey
A32: Bellmawr | B32: Camden | C32: 3400704750 | D32: borough | E32: queued | F32: 137 | G32: Sakura Sushi & Hibachi | H32: 2023-11-05 | I32: Sakura Sushi & Hibachi | J32: https://bellmawrsakura.com/ | K32: =IF(A32="","","https://en.wikipedia.org/wiki/"&SUBSTITUTE(A32," ","_")&IF(D32="township","_Township","")&",_New_Jersey") -> https://en.wikipedia.org/wiki/Bellmawr,_New_Jersey
A33: Belmar | B33: Monmouth | C33: 3402504930 | D33: borough | E33: pre-challenge | G33: Flames Brazillian Steakhouse | H33: 44940 | I33: Flames Brazilian Steakhouse | J33: http://flamesbraziliansteakhouse.com/ | K33: =IF(A33="","","https://en.wikipedia.org/wiki/"&SUBSTITUTE(A33," ","_")&IF(D33="township","_Township","")&",_New_Jersey") -> https://en.wikipedia.org/wiki/Belmar,_New_Jersey
A34: Belvidere | B34: Warren | C34: 3404104990 | D34: town | E34: queued | F34: 236 | G34: Uncle Buck's Diner | H34: 45571 | I34: Uncle Buck's Diner | K34: =IF(A34="","","https://en.wikipedia.org/wiki/"&SUBSTITUTE(A34," ","_")&IF(D34="township","_Township","")&",_New_Jersey") -> https://en.wikipedia.org/wiki/Belvidere,_New_Jersey
A35: Bergenfield | B35: Bergen | C35: 3400305170 | D35: borough | E35: unvisited | K35: =IF(A35="","","https://en.wikipedia.org/wiki/"&SUBSTITUTE(A35," ","_")&IF(D35="township","_Township","")&",_New_Jersey") -> https://en.wikipedia.org/wiki/Bergenfield,_New_Jersey
A36: Berkeley | B36: Ocean | C36: 3402905305 | D36: township | E36: queued | F36: 219 | G36: B2Bistro Waters Edge | H36: 45520 | I36: B2 Bistro + Bar | J36: https://www.b2bistro.com/ | K36: =IF(A36="","","https://en.wikipedia.org/wiki/"&SUBSTITUTE(A36," ","_")&IF(D36="township","_Township","")&",_New_Jersey") -> https://en.wikipedia.org/wiki/Berkeley_Township,_New_Jersey
A37: Berkeley Heights | B37: Union | C37: 3403905320 | D37: township | E37: unvisited | K37: =IF(A37="","","https://en.wikipedia.org/wiki/"&SUBSTITUTE(A37," ","_")&IF(D37="township","_Township","")&",_New_Jersey") -> https://en.wikipedia.org/wiki/Berkeley_Heights_Township,_New_Jersey
A38: Berlin | B38: Camden | C38: 3400705440 | D38: borough | E38: unvisited | K38: =IF(A38="","","https://en.wikipedia.org/wiki/"&SUBSTITUTE(A38," ","_")&IF(D38="township","_Township","")&",_New_Jersey") -> https://en.wikipedia.org/wiki/Berlin,_New_Jersey
A39: Berlin | B39: Camden | C39: 3400705470 | D39: township | E39: unvisited | K39: =IF(A39="","","https://en.wikipedia.org/wiki/"&SUBSTITUTE(A39," ","_")&IF(D39="township","_Township","")&",_New_Jersey") -> https://en.wikipedia.org/wiki/Berlin_Township,_New_Jersey
A40: Bernards | B40: Somerset | C40: 3403505560 | D40: township | E40: pre-challenge | G40: Olde Mill Inn | H40: 42861 | I40: Olde Mill Inn | J40: https://www.oldemillinn.com/ | K40: =IF(A40="","","https://en.wikipedia.org/wiki/"&SUBSTITUTE(A40," ","_")&IF(D40="township","_Township","")&",_New_Jersey") -> https://en.wikipedia.org/wiki/Bernards_Township,_New_Jersey
...

Sheet Summary
A1: EAT JERSEY CHALLENGE — Statewide Progress
A2: Total Towns | B2: Visited | C2: To Go | D2: % Complete
A3: =COUNTA(Data!A3:A602) -> 564 | B3: =COUNTIF(Data!E3:E602,"visited")+COUNTIF(Data!E3:E602,"queued")+COUNTIF(Data!E3:E602,"pre-challenge") -> 291 | C3: =A3-B3 -> 273 | D3: =IF(A3>0,TEXT(B3/A3,"0.0%"),"0.0%") -> 51.6%
A5: County | B5: Total Towns | C5: Visited | D5: To Go | E5: % Complete
A6: Atlantic | B6: =COUNTIF(Data!B3:B602,"Atlantic") -> 23 | C6: =COUNTIFS(Data!B3:B602,"Atlantic",Data!E3:E602,"visited")+COUNTIFS(Data!B3:B602,"Atlantic",Data!E3:E602,"queued")+COUNTIFS(Data!B3:B602,"Atlantic",Data!E3:E602,"pre-challenge") -> 8 | D6: =B6-C6 -> 15 | E6: =IF(B6>0,TEXT(C6/B6,"0.0%"),"0.0%") -> 34.8%
A7: Bergen | B7: =COUNTIF(Data!B3:B602,"Bergen") -> 70 | C7: =COUNTIFS(Data!B3:B602,"Bergen",Data!E3:E602,"visited")+COUNTIFS(Data!B3:B602,"Bergen",Data!E3:E602,"queued")+COUNTIFS(Data!B3:B602,"Bergen",Data!E3:E602,"pre-challenge") -> 19 | D7: =B7-C7 -> 51 | E7: =IF(B7>0,TEXT(C7/B7,"0.0%"),"0.0%") -> 27.1%
A8: Burlington | B8: =COUNTIF(Data!B3:B602,"Burlington") -> 40 | C8: =COUNTIFS(Data!B3:B602,"Burlington",Data!E3:E602,"visited")+COUNTIFS(Data!B3:B602,"Burlington",Data!E3:E602,"queued")+COUNTIFS(Data!B3:B602,"Burlington",Data!E3:E602,"pre-challenge") -> 20 | D8: =B8-C8 -> 20 | E8: =IF(B8>0,TEXT(C8/B8,"0.0%"),"0.0%") -> 50.0%
A9: Camden | B9: =COUNTIF(Data!B3:B602,"Camden") -> 36 | C9: =COUNTIFS(Data!B3:B602,"Camden",Data!E3:E602,"visited")+COUNTIFS(Data!B3:B602,"Camden",Data!E3:E602,"queued")+COUNTIFS(Data!B3:B602,"Camden",Data!E3:E602,"pre-challenge") -> 11 | D9: =B9-C9 -> 25 | E9: =IF(B9>0,TEXT(C9/B9,"0.0%"),"0.0%") -> 30.6%
A10: Cape May | B10: =COUNTIF(Data!B3:B602,"Cape May") -> 16 | C10: =COUNTIFS(Data!B3:B602,"Cape May",Data!E3:E602,"visited")+COUNTIFS(Data!B3:B602,"Cape May",Data!E3:E602,"queued")+COUNTIFS(Data!B3:B602,"Cape May",Data!E3:E602,"pre-challenge") -> 6 | D10: =B10-C10 -> 10 | E10: =IF(B10>0,TEXT(C10/B10,"0.0%"),"0.0%") -> 37.5%
A11: Cumberland | B11: =COUNTIF(Data!B3:B602,"Cumberland") -> 14 | C11: =COUNTIFS(Data!B3:B602,"Cumberland",Data!E3:E602,"visited")+COUNTIFS(Data!B3:B602,"Cumberland",Data!E3:E602,"queued")+COUNTIFS(Data!B3:B602,"Cumberland",Data!E3:E602,"pre-challenge") -> 14 | D11: =B11-C11 -> 0 | E11: =IF(B11>0,TEXT(C11/B11,"0.0%"),"0.0%") -> 100.0%
A12: Essex | B12: =COUNTIF(Data!B3:B602,"Essex") -> 22 | C12: =COUNTIFS(Data!B3:B602,"Essex",Data!E3:E602,"visited")+COUNTIFS(Data!B3:B602,"Essex",Data!E3:E602,"queued")+COUNTIFS(Data!B3:B602,"Essex",Data!E3:E602,"pre-challenge") -> 9 | D12: =B12-C12 -> 13 | E12: =IF(B12>0,TEXT(C12/B12,"0.0%"),"0.0%") -> 40.9%
A13: Gloucester | B13: =COUNTIF(Data!B3:B602,"Gloucester") -> 24 | C13: =COUNTIFS(Data!B3:B602,"Gloucester",Data!E3:E602,"visited")+COUNTIFS(Data!B3:B602,"Gloucester",Data!E3:E602,"queued")+COUNTIFS(Data!B3:B602,"Gloucester",Data!E3:E602,"pre-challenge") -> 10 | D13: =B13-C13 -> 14 | E13: =IF(B13>0,TEXT(C13/B13,"0.0%"),"0.0%") -> 41.7%
A14: Hudson | B14: =COUNTIF(Data!B3:B602,"Hudson") -> 12 | C14: =COUNTIFS(Data!B3:B602,"Hudson",Data!E3:E602,"visited")+COUNTIFS(Data!B3:B602,"Hudson",Data!E3:E602,"queued")+COUNTIFS(Data!B3:B602,"Hudson",Data!E3:E602,"pre-challenge") -> 11 | D14: =B14-C14 -> 1 | E14: =IF(B14>0,TEXT(C14/B14,"0.0%"),"0.0%") -> 91.7%
A15: Hunterdon | B15: =COUNTIF(Data!B3:B602,"Hunterdon") -> 26 | C15: =COUNTIFS(Data!B3:B602,"Hunterdon",Data!E3:E602,"visited")+COUNTIFS(Data!B3:B602,"Hunterdon",Data!E3:E602,"queued")+COUNTIFS(Data!B3:B602,"Hunterdon",Data!E3:E602,"pre-challenge") -> 13 | D15: =B15-C15 -> 13 | E15: =IF(B15>0,TEXT(C15/B15,"0.0%"),"0.0%") -> 50.0%
A16: Mercer | B16: =COUNTIF(Data!B3:B602,"Mercer") -> 12 | C16: =COUNTIFS(Data!B3:B602,"Mercer",Data!E3:E602,"visited")+COUNTIFS(Data!B3:B602,"Mercer",Data!E3:E602,"queued")+COUNTIFS(Data!B3:B602,"Mercer",Data!E3:E602,"pre-challenge") -> 10 | D16: =B16-C16 -> 2 | E16: =IF(B16>0,TEXT(C16/B16,"0.0%"),"0.0%") -> 83.3%
A17: Middlesex | B17: =COUNTIF(Data!B3:B602,"Middlesex") -> 25 | C17: =COUNTIFS(Data!B3:B602,"Middlesex",Data!E3:E602,"visited")+COUNTIFS(Data!B3:B602,"Middlesex",Data!E3:E602,"queued")+COUNTIFS(Data!B3:B602,"Middlesex",Data!E3:E602,"pre-challenge") -> 25 | D17: =B17-C17 -> 0 | E17: =IF(B17>0,TEXT(C17/B17,"0.0%"),"0.0%") -> 100.0%
A18: Monmouth | B18: =COUNTIF(Data!B3:B602,"Monmouth") -> 53 | C18: =COUNTIFS(Data!B3:B602,"Monmouth",Data!E3:E602,"visited")+COUNTIFS(Data!B3:B602,"Monmouth",Data!E3:E602,"queued")+COUNTIFS(Data!B3:B602,"Monmouth",Data!E3:E602,"pre-challenge") -> 44 | D18: =B18-C18 -> 9 | E18: =IF(B18>0,TEXT(C18/B18,"0.0%"),"0.0%") -> 83.0%
A19: Morris | B19: =COUNTIF(Data!B3:B602,"Morris") -> 39 | C19: =COUNTIFS(Data!B3:B602,"Morris",Data!E3:E602,"visited")+COUNTIFS(Data!B3:B602,"Morris",Data!E3:E602,"queued")+COUNTIFS(Data!B3:B602,"Morris",Data!E3:E602,"pre-challenge") -> 7 | D19: =B19-C19 -> 32 | E19: =IF(B19>0,TEXT(C19/B19,"0.0%"),"0.0%") -> 17.9%
A20: Ocean | B20: =COUNTIF(Data!B3:B602,"Ocean") -> 33 | C20: =COUNTIFS(Data!B3:B602,"Ocean",Data!E3:E602,"visited")+COUNTIFS(Data!B3:B602,"Ocean",Data!E3:E602,"queued")+COUNTIFS(Data!B3:B602,"Ocean",Data!E3:E602,"pre-challenge") -> 24 | D20: =B20-C20 -> 9 | E20: =IF(B20>0,TEXT(C20/B20,"0.0%"),"0.0%") -> 72.7%
A21: Passaic | B21: =COUNTIF(Data!B3:B602,"Passaic") -> 16 | C21: =COUNTIFS(Data!B3:B602,"Passaic",Data!E3:E602,"visited")+COUNTIFS(Data!B3:B602,"Passaic",Data!E3:E602,"queued")+COUNTIFS(Data!B3:B602,"Passaic",Data!E3:E602,"pre-challenge") -> 4 | D21: =B21-C21 -> 12 | E21: =IF(B21>0,TEXT(C21/B21,"0.0%"),"0.0%") -> 25.0%
A22: Salem | B22: =COUNTIF(Data!B3:B602,"Salem") -> 15 | C22: =COUNTIFS(Data!B3:B602,"Salem",Data!E3:E602,"visited")+COUNTIFS(Data!B3:B602,"Salem",Data!E3:E602,"queued")+COUNTIFS(Data!B3:B602,"Salem",Data!E3:E602,"pre-challenge") -> 10 | D22: =B22-C22 -> 5 | E22: =IF(B22>0,TEXT(C22/B22,"0.0%"),"0.0%") -> 66.7%
A23: Somerset | B23: =COUNTIF(Data!B3:B602,"Somerset") -> 21 | C23: =COUNTIFS(Data!B3:B602,"Somerset",Data!E3:E602,"visited")+COUNTIFS(Data!B3:B602,"Somerset",Data!E3:E602,"queued")+COUNTIFS(Data!B3:B602,"Somerset",Data!E3:E602,"pre-challenge") -> 12 | D23: =B23-C23 -> 9 | E23: =IF(B23>0,TEXT(C23/B23,"0.0%"),"0.0%") -> 57.1%
A24: Sussex | B24: =COUNTIF(Data!B3:B602,"Sussex") -> 24 | C24: =COUNTIFS(Data!B3:B602,"Sussex",Data!E3:E602,"visited")+COUNTIFS(Data!B3:B602,"Sussex",Data!E3:E602,"queued")+COUNTIFS(Data!B3:B602,"Sussex",Data!E3:E602,"pre-challenge") -> 12 | D24: =B24-C24 -> 12 | E24: =IF(B24>0,TEXT(C24/B24,"0.0%"),"0.0%") -> 50.0%
A25: Union | B25: =COUNTIF(Data!B3:B602,"Union") -> 21 | C25: =COUNTIFS(Data!B3:B602,"Union",Data!E3:E602,"visited")+COUNTIFS(Data!B3:B602,"Union",Data!E3:E602,"queued")+COUNTIFS(Data!B3:B602,"Union",Data!E3:E602,"pre-challenge") -> 10 | D25: =B25-C25 -> 11 | E25: =IF(B25>0,TEXT(C25/B25,"0.0%"),"0.0%") -> 47.6%
A26: Warren | B26: =COUNTIF(Data!B3:B602,"Warren") -> 22 | C26: =COUNTIFS(Data!B3:B602,"Warren",Data!E3:E602,"visited")+COUNTIFS(Data!B3:B602,"Warren",Data!E3:E602,"queued")+COUNTIFS(Data!B3:B602,"Warren",Data!E3:E602,"pre-challenge") -> 12 | D26: =B26-C26 -> 10 | E26: =IF(B26>0,TEXT(C26/B26,"0.0%"),"0.0%") -> 54.5%

Sheet Atlantic
A1: Atlantic County
A2: Total Towns | B2: =COUNTIF(Data!B$3:B$602,"Atlantic") -> 23 | C2: Visited | D2: =COUNTIFS(Data!B$3:B$602,"Atlantic",Data!E3:E602,"visited")+COUNTIFS(Data!B$3:B$602,"Atlantic",Data!E3:E602,"queued")+COUNTIFS(Data!B$3:B$602,"Atlantic",Data!E3:E602,"pre-challenge") -> 8 | E2: To Go | F2: =B2-D2 -> 15
A4: MUNICIPALITY | E4: VISIT DATA | I4: RESTAURANT LINK | K4: WIKIPEDIA | L4: INSTAGRAM | P4: TIKTOK | T4: YOUTUBE | X4: THREADS | AB4: BLUESKY | AF4: FACEBOOK | AJ4: EXTRA / OVERFLOW LINKS
A5: name | B5: county | C5: geoid | D5: townType | E5: status | F5: visitNumber | G5: restaurantName | H5: dateVisited | I5: restaurant_label | J5: restaurant_url | K5: wikipedia_url | L5: instagram1_label | M5: instagram1_url | N5: instagram2_label | O5: instagram2_url | P5: tiktok1_label | Q5: tiktok1_url | R5: tiktok2_label | S5: tiktok2_url | T5: youtube1_label | U5: youtube1_url | V5: youtube2_label | W5: youtube2_url | X5: threads1_label | Y5: threads1_url | Z5: threads2_label | AA5: threads2_url | AB5: bluesky1_label | AC5: bluesky1_url | AD5: bluesky2_label | AE5: bluesky2_url | AF5: facebook1_label | AG5: facebook1_url | AH5: facebook2_label | AI5: facebook2_url | AJ5: extra1_category | AK5: extra1_platform | AL5: extra1_label | AM5: extra1_url | AN5: extra2_category | AO5: extra2_platform | AP5: extra2_label | AQ5: extra2_url | AR5: extra3_category | AS5: extra3_platform | AT5: extra3_label | AU5: extra3_url
A6: {=_xlfn._xlws.FILTER(Data!A$3:AU$602,Data!B$3:B$602="Atlantic","")} -> Absecon | B6: Atlantic | C6: 3400100100 | D6: city | E6: unvisited | F6: 0 | G6: 0 | H6: 0 | I6: 0 | J6: 0 | K6: https://en.wikipedia.org/wiki/Absecon,_New_Jersey | L6: 0 | M6: 0 | N6: 0 | O6: 0 | P6: 0 | Q6: 0 | R6: 0 | S6: 0 | T6: 0 | U6: 0 | V6: 0 | W6: 0 | X6: 0 | Y6: 0 | Z6: 0 | AA6: 0 | AB6: 0 | AC6: 0 | AD6: 0 | AE6: 0 | AF6: 0 | AG6: 0 | AH6: 0 | AI6: 0 | AJ6: 0 | AK6: 0 | AL6: 0 | AM6: 0 | AN6: 0 | AO6: 0 | AP6: 0 | AQ6: 0 | AR6: 0 | AS6: 0 | AT6: 0 | AU6: 0
A7: Atlantic City | B7: Atlantic | C7: 3400102080 | D7: city | E7: pre-challenge | F7: 0 | G7: Amada | H7: 43639 | I7: Amada | J7: https://www.theoceanac.com/restaurants/amada | K7: https://en.wikipedia.org/wiki/Atlantic_City,_New_Jersey | L7: 0 | M7: 0 | N7: 0 | O7: 0 | P7: 0 | Q7: 0 | R7: 0 | S7: 0 | T7: 0 | U7: 0 | V7: 0 | W7: 0 | X7: 0 | Y7: 0 | Z7: 0 | AA7: 0 | AB7: 0 | AC7: 0 | AD7: 0 | AE7: 0 | AF7: 0 | AG7: 0 | AH7: 0 | AI7: 0 | AJ7: 0 | AK7: 0 | AL7: 0 | AM7: 0 | AN7: 0 | AO7: 0 | AP7: 0 | AQ7: 0 | AR7: 0 | AS7: 0 | AT7: 0 | AU7: 0
A8: Brigantine | B8: Atlantic | C8: 3400107810 | D8: city | E8: pre-challenge | F8: 0 | G8: Yianni's Café | H8: 43678 | I8: Yianni's Café | J8: https://yianniscafeoc.com/ | K8: https://en.wikipedia.org/wiki/Brigantine,_New_Jersey | L8: 0 | M8: 0 | N8: 0 | O8: 0 | P8: 0 | Q8: 0 | R8: 0 | S8: 0 | T8: 0 | U8: 0 | V8: 0 | W8: 0 | X8: 0 | Y8: 0 | Z8: 0 | AA8: 0 | AB8: 0 | AC8: 0 | AD8: 0 | AE8: 0 | AF8: 0 | AG8: 0 | AH8: 0 | AI8: 0 | AJ8: 0 | AK8: 0 | AL8: 0 | AM8: 0 | AN8: 0 | AO8: 0 | AP8: 0 | AQ8: 0 | AR8: 0 | AS8: 0 | AT8: 0 | AU8: 0
A9: Buena | B9: Atlantic | C9: 3400108680 | D9: borough | E9: unvisited | F9: 0 | G9: 0 | H9: 0 | I9: 0 | J9: 0 | K9: https://en.wikipedia.org/wiki/Buena,_New_Jersey | L9: 0 | M9: 0 | N9: 0 | O9: 0 | P9: 0 | Q9: 0 | R9: 0 | S9: 0 | T9: 0 | U9: 0 | V9: 0 | W9: 0 | X9: 0 | Y9: 0 | Z9: 0 | AA9: 0 | AB9: 0 | AC9: 0 | AD9: 0 | AE9: 0 | AF9: 0 | AG9: 0 | AH9: 0 | AI9: 0 | AJ9: 0 | AK9: 0 | AL9: 0 | AM9: 0 | AN9: 0 | AO9: 0 | AP9: 0 | AQ9: 0 | AR9: 0 | AS9: 0 | AT9: 0 | AU9: 0
A10: Buena Vista | B10: Atlantic | C10: 3400108710 | D10: township | E10: unvisited | F10: 0 | G10: 0 | H10: 0 | I10: 0 | J10: 0 | K10: https://en.wikipedia.org/wiki/Buena_Vista_Township,_New_Jersey | L10: 0 | M10: 0 | N10: 0 | O10: 0 | P10: 0 | Q10: 0 | R10: 0 | S10: 0 | T10: 0 | U10: 0 | V10: 0 | W10: 0 | X10: 0 | Y10: 0 | Z10: 0 | AA10: 0 | AB10: 0 | AC10: 0 | AD10: 0 | AE10: 0 | AF10: 0 | AG10: 0 | AH10: 0 | AI10: 0 | AJ10: 0 | AK10: 0 | AL10: 0 | AM10: 0 | AN10: 0 | AO10: 0 | AP10: 0 | AQ10: 0 | AR10: 0 | AS10: 0 | AT10: 0 | AU10: 0
A11: Corbin City | B11: Atlantic | C11: 3400115160 | D11: city | E11: unvisited | F11: 0 | G11: 0 | H11: 0 | I11: 0 | J11: 0 | K11: https://en.wikipedia.org/wiki/Corbin_City,_New_Jersey | L11: 0 | M11: 0 | N11: 0 | O11: 0 | P11: 0 | Q11: 0 | R11: 0 | S11: 0 | T11: 0 | U11: 0 | V11: 0 | W11: 0 | X11: 0 | Y11: 0 | Z11: 0 | AA11: 0 | AB11: 0 | AC11: 0 | AD11: 0 | AE11: 0 | AF11: 0 | AG11: 0 | AH11: 0 | AI11: 0 | AJ11: 0 | AK11: 0 | AL11: 0 | AM11: 0 | AN11: 0 | AO11: 0 | AP11: 0 | AQ11: 0 | AR11: 0 | AS11: 0 | AT11: 0 | AU11: 0
A12: Egg Harbor | B12: Atlantic | C12: 3400120290 | D12: township | E12: queued | F12: 260 | G12: Family Kusina | H12: 45660 | I12: Familya Kusina | J12: https://www.familyakusina.com/ | K12: https://en.wikipedia.org/wiki/Egg_Harbor_Township,_New_Jersey | L12: 0 | M12: 0 | N12: 0 | O12: 0 | P12: 0 | Q12: 0 | R12: 0 | S12: 0 | T12: 0 | U12: 0 | V12: 0 | W12: 0 | X12: 0 | Y12: 0 | Z12: 0 | AA12: 0 | AB12: 0 | AC12: 0 | AD12: 0 | AE12: 0 | AF12: 0 | AG12: 0 | AH12: 0 | AI12: 0 | AJ12: 0 | AK12: 0 | AL12: 0 | AM12: 0 | AN12: 0 | AO12: 0 | AP12: 0 | AQ12: 0 | AR12: 0 | AS12: 0 | AT12: 0 | AU12: 0
A13: Egg Harbor City | B13: Atlantic | C13: 3400120350 | D13: city | E13: unvisited | F13: 0 | G13: 0 | H13: 0 | I13: 0 | J13: 0 | K13: https://en.wikipedia.org/wiki/Egg_Harbor_City,_New_Jersey | L13: 0 | M13: 0 | N13: 0 | O13: 0 | P13: 0 | Q13: 0 | R13: 0 | S13: 0 | T13: 0 | U13: 0 | V13: 0 | W13: 0 | X13: 0 | Y13: 0 | Z13: 0 | AA13: 0 | AB13: 0 | AC13: 0 | AD13: 0 | AE13: 0 | AF13: 0 | AG13: 0 | AH13: 0 | AI13: 0 | AJ13: 0 | AK13: 0 | AL13: 0 | AM13: 0 | AN13: 0 | AO13: 0 | AP13: 0 | AQ13: 0 | AR13: 0 | AS13: 0 | AT13: 0 | AU13: 0
A14: Estell Manor | B14: Atlantic | C14: 3400121870 | D14: city | E14: unvisited | F14: 0 | G14: 0 | H14: 0 | I14: 0 | J14: 0 | K14: https://en.wikipedia.org/wiki/Estell_Manor,_New_Jersey | L14: 0 | M14: 0 | N14: 0 | O14: 0 | P14: 0 | Q14: 0 | R14: 0 | S14: 0 | T14: 0 | U14: 0 | V14: 0 | W14: 0 | X14: 0 | Y14: 0 | Z14: 0 | AA14: 0 | AB14: 0 | AC14: 0 | AD14: 0 | AE14: 0 | AF14: 0 | AG14: 0 | AH14: 0 | AI14: 0 | AJ14: 0 | AK14: 0 | AL14: 0 | AM14: 0 | AN14: 0 | AO14: 0 | AP14: 0 | AQ14: 0 | AR14: 0 | AS14: 0 | AT14: 0 | AU14: 0
A15: Folsom | B15: Atlantic | C15: 3400123940 | D15: borough | E15: unvisited | F15: 0 | G15: 0 | H15: 0 | I15: 0 | J15: 0 | K15: https://en.wikipedia.org/wiki/Folsom,_New_Jersey | L15: 0 | M15: 0 | N15: 0 | O15: 0 | P15: 0 | Q15: 0 | R15: 0 | S15: 0 | T15: 0 | U15: 0 | V15: 0 | W15: 0 | X15: 0 | Y15: 0 | Z15: 0 | AA15: 0 | AB15: 0 | AC15: 0 | AD15: 0 | AE15: 0 | AF15: 0 | AG15: 0 | AH15: 0 | AI15: 0 | AJ15: 0 | AK15: 0 | AL15: 0 | AM15: 0 | AN15: 0 | AO15: 0 | AP15: 0 | AQ15: 0 | AR15: 0 | AS15: 0 | AT15: 0 | AU15: 0
A16: Galloway | B16: Atlantic | C16: 3400125560 | D16: township | E16: pre-challenge | F16: 0 | G16: Seaview Hotel | H16: 43639 | I16: Seaview Hotel | J16: https://www.seaviewdolcehotel.com/ | K16: https://en.wikipedia.org/wiki/Galloway_Township,_New_Jersey | L16: 0 | M16: 0 | N16: 0 | O16: 0 | P16: 0 | Q16: 0 | R16: 0 | S16: 0 | T16: 0 | U16: 0 | V16: 0 | W16: 0 | X16: 0 | Y16: 0 | Z16: 0 | AA16: 0 | AB16: 0 | AC16: 0 | AD16: 0 | AE16: 0 | AF16: 0 | AG16: 0 | AH16: 0 | AI16: 0 | AJ16: 0 | AK16: 0 | AL16: 0 | AM16: 0 | AN16: 0 | AO16: 0 | AP16: 0 | AQ16: 0 | AR16: 0 | AS16: 0 | AT16: 0 | AU16: 0
A17: Hamilton | B17: Atlantic | C17: 3400129280 | D17: township | E17: unvisited | F17: 0 | G17: 0 | H17: 0 | I17: 0 | J17: 0 | K17: https://en.wikipedia.org/wiki/Hamilton_Township,_Atlantic_County,_New_Jersey | L17: 0 | M17: 0 | N17: 0 | O17: 0 | P17: 0 | Q17: 0 | R17: 0 | S17: 0 | T17: 0 | U17: 0 | V17: 0 | W17: 0 | X17: 0 | Y17: 0 | Z17: 0 | AA17: 0 | AB17: 0 | AC17: 0 | AD17: 0 | AE17: 0 | AF17: 0 | AG17: 0 | AH17: 0 | AI17: 0 | AJ17: 0 | AK17: 0 | AL17: 0 | AM17: 0 | AN17: 0 | AO17: 0 | AP17: 0 | AQ17: 0 | AR17: 0 | AS17: 0 | AT17: 0 | AU17: 0
A18: Hammonton | B18: Atlantic | C18: 3400129430 | D18: town | E18: unvisited | F18: 0 | G18: 0 | H18: 0 | I18: 0 | J18: 0 | K18: https://en.wikipedia.org/wiki/Hammonton,_New_Jersey | L18: 0 | M18: 0 | N18: 0 | O18: 0 | P18: 0 | Q18: 0 | R18: 0 | S18: 0 | T18: 0 | U18: 0 | V18: 0 | W18: 0 | X18: 0 | Y18: 0 | Z18: 0 | AA18: 0 | AB18: 0 | AC18: 0 | AD18: 0 | AE18: 0 | AF18: 0 | AG18: 0 | AH18: 0 | AI18: 0 | AJ18: 0 | AK18: 0 | AL18: 0 | AM18: 0 | AN18: 0 | AO18: 0 | AP18: 0 | AQ18: 0 | AR18: 0 | AS18: 0 | AT18: 0 | AU18: 0
A19: Linwood | B19: Atlantic | C19: 3400140530 | D19: city | E19: queued | F19: 259 | G19: Barista's Coffee House | H19: 45660 | I19: Barista's Coffee House | J19: https://www.baristascoffeehouse.com/ | K19: https://en.wikipedia.org/wiki/Linwood,_New_Jersey | L19: 0 | M19: 0 | N19: 0 | O19: 0 | P19: 0 | Q19: 0 | R19: 0 | S19: 0 | T19: 0 | U19: 0 | V19: 0 | W19: 0 | X19: 0 | Y19: 0 | Z19: 0 | AA19: 0 | AB19: 0 | AC19: 0 | AD19: 0 | AE19: 0 | AF19: 0 | AG19: 0 | AH19: 0 | AI19: 0 | AJ19: 0 | AK19: 0 | AL19: 0 | AM19: 0 | AN19: 0 | AO19: 0 | AP19: 0 | AQ19: 0 | AR19: 0 | AS19: 0 | AT19: 0 | AU19: 0
A20: Longport | B20: Atlantic | C20: 3400141370 | D20: borough | E20: queued | F20: 249 | G20: Ozzie's Luncheonette | H20: 45619 | I20: Ozzie's Luncheonette | J20: https://ozzieslongport.com/ | K20: https://en.wikipedia.org/wiki/Longport,_New_Jersey | L20: 0 | M20: 0 | N20: 0 | O20: 0 | P20: 0 | Q20: 0 | R20: 0 | S20: 0 | T20: 0 | U20: 0 | V20: 0 | W20: 0 | X20: 0 | Y20: 0 | Z20: 0 | AA20: 0 | AB20: 0 | AC20: 0 | AD20: 0 | AE20: 0 | AF20: 0 | AG20: 0 | AH20: 0 | AI20: 0 | AJ20: 0 | AK20: 0 | AL20: 0 | AM20: 0 | AN20: 0 | AO20: 0 | AP20: 0 | AQ20: 0 | AR20: 0 | AS20: 0 | AT20: 0 | AU20: 0
A21: Margate City | B21: Atlantic | C21: 3400143890 | D21: city | E21: unvisited | F21: 0 | G21: 0 | H21: 0 | I21: 0 | J21: 0 | K21: https://en.wikipedia.org/wiki/Margate_City,_New_Jersey | L21: 0 | M21: 0 | N21: 0 | O21: 0 | P21: 0 | Q21: 0 | R21: 0 | S21: 0 | T21: 0 | U21: 0 | V21: 0 | W21: 0 | X21: 0 | Y21: 0 | Z21: 0 | AA21: 0 | AB21: 0 | AC21: 0 | AD21: 0 | AE21: 0 | AF21: 0 | AG21: 0 | AH21: 0 | AI21: 0 | AJ21: 0 | AK21: 0 | AL21: 0 | AM21: 0 | AN21: 0 | AO21: 0 | AP21: 0 | AQ21: 0 | AR21: 0 | AS21: 0 | AT21: 0 | AU21: 0
A22: Mullica | B22: Atlantic | C22: 3400149410 | D22: township | E22: unvisited | F22: 0 | G22: 0 | H22: 0 | I22: 0 | J22: 0 | K22: https://en.wikipedia.org/wiki/Mullica_Township,_New_Jersey | L22: 0 | M22: 0 | N22: 0 | O22: 0 | P22: 0 | Q22: 0 | R22: 0 | S22: 0 | T22: 0 | U22: 0 | V22: 0 | W22: 0 | X22: 0 | Y22: 0 | Z22: 0 | AA22: 0 | AB22: 0 | AC22: 0 | AD22: 0 | AE22: 0 | AF22: 0 | AG22: 0 | AH22: 0 | AI22: 0 | AJ22: 0 | AK22: 0 | AL22: 0 | AM22: 0 | AN22: 0 | AO22: 0 | AP22: 0 | AQ22: 0 | AR22: 0 | AS22: 0 | AT22: 0 | AU22: 0
A23: Northfield | B23: Atlantic | C23: 3400152950 | D23: city | E23: pre-challenge | F23: 0 | G23: Venture's Offshore Café | H23: 45619 | I23: Ventura's Offshore Café | J23: https://www.venturascafe.com/ | K23: https://en.wikipedia.org/wiki/Northfield,_New_Jersey | L23: 0 | M23: 0 | N23: 0 | O23: 0 | P23: 0 | Q23: 0 | R23: 0 | S23: 0 | T23: 0 | U23: 0 | V23: 0 | W23: 0 | X23: 0 | Y23: 0 | Z23: 0 | AA23: 0 | AB23: 0 | AC23: 0 | AD23: 0 | AE23: 0 | AF23: 0 | AG23: 0 | AH23: 0 | AI23: 0 | AJ23: 0 | AK23: 0 | AL23: 0 | AM23: 0 | AN23: 0 | AO23: 0 | AP23: 0 | AQ23: 0 | AR23: 0 | AS23: 0 | AT23: 0 | AU23: 0
A24: Pleasantville | B24: Atlantic | C24: 3400159640 | D24: city | E24: unvisited | F24: 0 | G24: 0 | H24: 0 | I24: 0 | J24: 0 | K24: https://en.wikipedia.org/wiki/Pleasantville,_New_Jersey | L24: 0 | M24: 0 | N24: 0 | O24: 0 | P24: 0 | Q24: 0 | R24: 0 | S24: 0 | T24: 0 | U24: 0 | V24: 0 | W24: 0 | X24: 0 | Y24: 0 | Z24: 0 | AA24: 0 | AB24: 0 | AC24: 0 | AD24: 0 | AE24: 0 | AF24: 0 | AG24: 0 | AH24: 0 | AI24: 0 | AJ24: 0 | AK24: 0 | AL24: 0 | AM24: 0 | AN24: 0 | AO24: 0 | AP24: 0 | AQ24: 0 | AR24: 0 | AS24: 0 | AT24: 0 | AU24: 0
A25: Port Republic | B25: Atlantic | C25: 3400160600 | D25: city | E25: unvisited | F25: 0 | G25: 0 | H25: 0 | I25: 0 | J25: 0 | K25: https://en.wikipedia.org/wiki/Port_Republic,_New_Jersey | L25: 0 | M25: 0 | N25: 0 | O25: 0 | P25: 0 | Q25: 0 | R25: 0 | S25: 0 | T25: 0 | U25: 0 | V25: 0 | W25: 0 | X25: 0 | Y25: 0 | Z25: 0 | AA25: 0 | AB25: 0 | AC25: 0 | AD25: 0 | AE25: 0 | AF25: 0 | AG25: 0 | AH25: 0 | AI25: 0 | AJ25: 0 | AK25: 0 | AL25: 0 | AM25: 0 | AN25: 0 | AO25: 0 | AP25: 0 | AQ25: 0 | AR25: 0 | AS25: 0 | AT25: 0 | AU25: 0
A26: Somers Point | B26: Atlantic | C26: 3400168430 | D26: city | E26: pre-challenge | F26: 0 | G26: Manco & Manco | H26: 44250 | I26: Manco and Manco | J26: https://mancospizza.com/ | K26: https://en.wikipedia.org/wiki/Somers_Point,_New_Jersey | L26: 0 | M26: 0 | N26: 0 | O26: 0 | P26: 0 | Q26: 0 | R26: 0 | S26: 0 | T26: 0 | U26: 0 | V26: 0 | W26: 0 | X26: 0 | Y26: 0 | Z26: 0 | AA26: 0 | AB26: 0 | AC26: 0 | AD26: 0 | AE26: 0 | AF26: 0 | AG26: 0 | AH26: 0 | AI26: 0 | AJ26: 0 | AK26: 0 | AL26: 0 | AM26: 0 | AN26: 0 | AO26: 0 | AP26: 0 | AQ26: 0 | AR26: 0 | AS26: 0 | AT26: 0 | AU26: 0
A27: Ventnor City | B27: Atlantic | C27: 3400175620 | D27: city | E27: unvisited | F27: 0 | G27: 0 | H27: 0 | I27: 0 | J27: 0 | K27: https://en.wikipedia.org/wiki/Ventnor_City,_New_Jersey | L27: 0 | M27: 0 | N27: 0 | O27: 0 | P27: 0 | Q27: 0 | R27: 0 | S27: 0 | T27: 0 | U27: 0 | V27: 0 | W27: 0 | X27: 0 | Y27: 0 | Z27: 0 | AA27: 0 | AB27: 0 | AC27: 0 | AD27: 0 | AE27: 0 | AF27: 0 | AG27: 0 | AH27: 0 | AI27: 0 | AJ27: 0 | AK27: 0 | AL27: 0 | AM27: 0 | AN27: 0 | AO27: 0 | AP27: 0 | AQ27: 0 | AR27: 0 | AS27: 0 | AT27: 0 | AU27: 0
A28: Weymouth | B28: Atlantic | C28: 3400180330 | D28: township | E28: unvisited | F28: 0 | G28: 0 | H28: 0 | I28: 0 | J28: 0 | K28: https://en.wikipedia.org/wiki/Weymouth_Township,_New_Jersey | L28: 0 | M28: 0 | N28: 0 | O28: 0 | P28: 0 | Q28: 0 | R28: 0 | S28: 0 | T28: 0 | U28: 0 | V28: 0 | W28: 0 | X28: 0 | Y28: 0 | Z28: 0 | AA28: 0 | AB28: 0 | AC28: 0 | AD28: 0 | AE28: 0 | AF28: 0 | AG28: 0 | AH28: 0 | AI28: 0 | AJ28: 0 | AK28: 0 | AL28: 0 | AM28: 0 | AN28: 0 | AO28: 0 | AP28: 0 | AQ28: 0 | AR28: 0 | AS28: 0 | AT28: 0 | AU28: 0

Sheet Bergen
A1: Bergen County
A2: Total Towns | B2: =COUNTIF(Data!B$3:B$602,"Bergen") -> 70 | C2: Visited | D2: =COUNTIFS(Data!B$3:B$602,"Bergen",Data!E3:E602,"visited")+COUNTIFS(Data!B$3:B$602,"Bergen",Data!E3:E602,"queued")+COUNTIFS(Data!B$3:B$602,"Bergen",Data!E3:E602,"pre-challenge") -> 19 | E2: To Go | F2: =B2-D2 -> 51
A4: MUNICIPALITY | E4: VISIT DATA | I4: RESTAURANT LINK | K4: WIKIPEDIA | L4: INSTAGRAM | P4: TIKTOK | T4: YOUTUBE | X4: THREADS | AB4: BLUESKY | AF4: FACEBOOK | AJ4: EXTRA / OVERFLOW LINKS
A5: name | B5: county | C5: geoid | D5: townType | E5: status | F5: visitNumber | G5: restaurantName | H5: dateVisited | I5: restaurant_label | J5: restaurant_url | K5: wikipedia_url | L5: instagram1_label | M5: instagram1_url | N5: instagram2_label | O5: instagram2_url | P5: tiktok1_label | Q5: tiktok1_url | R5: tiktok2_label | S5: tiktok2_url | T5: youtube1_label | U5: youtube1_url | V5: youtube2_label | W5: youtube2_url | X5: threads1_label | Y5: threads1_url | Z5: threads2_label | AA5: threads2_url | AB5: bluesky1_label | AC5: bluesky1_url | AD5: bluesky2_label | AE5: bluesky2_url | AF5: facebook1_label | AG5: facebook1_url | AH5: facebook2_label | AI5: facebook2_url | AJ5: extra1_category | AK5: extra1_platform | AL5: extra1_label | AM5: extra1_url | AN5: extra2_category | AO5: extra2_platform | AP5: extra2_label | AQ5: extra2_url | AR5: extra3_category | AS5: extra3_platform | AT5: extra3_label | AU5: extra3_url
A6: {=_xlfn._xlws.FILTER(Data!A$3:AU$602,Data!B$3:B$602="Bergen","")} -> Allendale | B6: Bergen | C6: 3400300700 | D6: borough | E6: unvisited | F6: 0 | G6: 0 | H6: 0 | I6: 0 | J6: 0 | K6: https://en.wikipedia.org/wiki/Allendale,_New_Jersey | L6: 0 | M6: 0 | N6: 0 | O6: 0 | P6: 0 | Q6: 0 | R6: 0 | S6: 0 | T6: 0 | U6: 0 | V6: 0 | W6: 0 | X6: 0 | Y6: 0 | Z6: 0 | AA6: 0 | AB6: 0 | AC6: 0 | AD6: 0 | AE6: 0 | AF6: 0 | AG6: 0 | AH6: 0 | AI6: 0 | AJ6: 0 | AK6: 0 | AL6: 0 | AM6: 0 | AN6: 0 | AO6: 0 | AP6: 0 | AQ6: 0 | AR6: 0 | AS6: 0 | AT6: 0 | AU6: 0
A7: Alpine | B7: Bergen | C7: 3400301090 | D7: borough | E7: queued | F7: 239 | G7: Kiku Japanese Steakhouse | H7: 2024-10-11 | I7: Kiku Japanese Steakhouse | J7: https://www.kikurestaurantsnj.com/ | K7: https://en.wikipedia.org/wiki/Alpine,_New_Jersey | L7: 0 | M7: 0 | N7: 0 | O7: 0 | P7: 0 | Q7: 0 | R7: 0 | S7: 0 | T7: 0 | U7: 0 | V7: 0 | W7: 0 | X7: 0 | Y7: 0 | Z7: 0 | AA7: 0 | AB7: 0 | AC7: 0 | AD7: 0 | AE7: 0 | AF7: 0 | AG7: 0 | AH7: 0 | AI7: 0 | AJ7: 0 | AK7: 0 | AL7: 0 | AM7: 0 | AN7: 0 | AO7: 0 | AP7: 0 | AQ7: 0 | AR7: 0 | AS7: 0 | AT7: 0 | AU7: 0
A8: Bergenfield | B8: Bergen | C8: 3400305170 | D8: borough | E8: unvisited | F8: 0 | G8: 0 | H8: 0 | I8: 0 | J8: 0 | K8: https://en.wikipedia.org/wiki/Bergenfield,_New_Jersey | L8: 0 | M8: 0 | N8: 0 | O8: 0 | P8: 0 | Q8: 0 | R8: 0 | S8: 0 | T8: 0 | U8: 0 | V8: 0 | W8: 0 | X8: 0 | Y8: 0 | Z8: 0 | AA8: 0 | AB8: 0 | AC8: 0 | AD8: 0 | AE8: 0 | AF8: 0 | AG8: 0 | AH8: 0 | AI8: 0 | AJ8: 0 | AK8: 0 | AL8: 0 | AM8: 0 | AN8: 0 | AO8: 0 | AP8: 0 | AQ8: 0 | AR8: 0 | AS8: 0 | AT8: 0 | AU8: 0
A9: Bogota | B9: Bergen | C9: 3400306490 | D9: borough | E9: unvisited | F9: 0 | G9: 0 | H9: 0 | I9: 0 | J9: 0 | K9: https://en.wikipedia.org/wiki/Bogota,_New_Jersey | L9: 0 | M9: 0 | N9: 0 | O9: 0 | P9: 0 | Q9: 0 | R9: 0 | S9: 0 | T9: 0 | U9: 0 | V9: 0 | W9: 0 | X9: 0 | Y9: 0 | Z9: 0 | AA9: 0 | AB9: 0 | AC9: 0 | AD9: 0 | AE9: 0 | AF9: 0 | AG9: 0 | AH9: 0 | AI9: 0 | AJ9: 0 | AK9: 0 | AL9: 0 | AM9: 0 | AN9: 0 | AO9: 0 | AP9: 0 | AQ9: 0 | AR9: 0 | AS9: 0 | AT9: 0 | AU9: 0
A10: Carlstadt | B10: Bergen | C10: 3400310480 | D10: borough | E10: queued | F10: 215 | G10: Biggie's Clam Bar | H10: 2024-07-17 | I10: Biggie's Clam Bar | J10: https://biggies.com/ | K10: https://en.wikipedia.org/wiki/Carlstadt,_New_Jersey | L10: 0 | M10: 0 | N10: 0 | O10: 0 | P10: 0 | Q10: 0 | R10: 0 | S10: 0 | T10: 0 | U10: 0 | V10: 0 | W10: 0 | X10: 0 | Y10: 0 | Z10: 0 | AA10: 0 | AB10: 0 | AC10: 0 | AD10: 0 | AE10: 0 | AF10: 0 | AG10: 0 | AH10: 0 | AI10: 0 | AJ10: 0 | AK10: 0 | AL10: 0 | AM10: 0 | AN10: 0 | AO10: 0 | AP10: 0 | AQ10: 0 | AR10: 0 | AS10: 0 | AT10: 0 | AU10: 0
A11: Cliffside Park | B11: Bergen | C11: 3400313570 | D11: borough | E11: queued | F11: 163 | G11: Mirak - Korean/Japanese Sushi Restauarant | H11: 2023-01-02 | I11: Mirak | J11: https://mirakcliffsidepark.com/ | K11: https://en.wikipedia.org/wiki/Cliffside_Park,_New_Jersey | L11: 0 | M11: 0 | N11: 0 | O11: 0 | P11: 0 | Q11: 0 | R11: 0 | S11: 0 | T11: 0 | U11: 0 | V11: 0 | W11: 0 | X11: 0 | Y11: 0 | Z11: 0 | AA11: 0 | AB11: 0 | AC11: 0 | AD11: 0 | AE11: 0 | AF11: 0 | AG11: 0 | AH11: 0 | AI11: 0 | AJ11: 0 | AK11: 0 | AL11: 0 | AM11: 0 | AN11: 0 | AO11: 0 | AP11: 0 | AQ11: 0 | AR11: 0 | AS11: 0 | AT11: 0 | AU11: 0
A12: Closter | B12: Bergen | C12: 3400313810 | D12: borough | E12: unvisited | F12: 0 | G12: 0 | H12: 0 | I12: 0 | J12: 0 | K12: https://en.wikipedia.org/wiki/Closter,_New_Jersey | L12: 0 | M12: 0 | N12: 0 | O12: 0 | P12: 0 | Q12: 0 | R12: 0 | S12: 0 | T12: 0 | U12: 0 | V12: 0 | W12: 0 | X12: 0 | Y12: 0 | Z12: 0 | AA12: 0 | AB12: 0 | AC12: 0 | AD12: 0 | AE12: 0 | AF12: 0 | AG12: 0 | AH12: 0 | AI12: 0 | AJ12: 0 | AK12: 0 | AL12: 0 | AM12: 0 | AN12: 0 | AO12: 0 | AP12: 0 | AQ12: 0 | AR12: 0 | AS12: 0 | AT12: 0 | AU12: 0
A13: Cresskill | B13: Bergen | C13: 3400315820 | D13: borough | E13: unvisited | F13: 0 | G13: 0 | H13: 0 | I13: 0 | J13: 0 | K13: https://en.wikipedia.org/wiki/Cresskill,_New_Jersey | L13: 0 | M13: 0 | N13: 0 | O13: 0 | P13: 0 | Q13: 0 | R13: 0 | S13: 0 | T13: 0 | U13: 0 | V13: 0 | W13: 0 | X13: 0 | Y13: 0 | Z13: 0 | AA13: 0 | AB13: 0 | AC13: 0 | AD13: 0 | AE13: 0 | AF13: 0 | AG13: 0 | AH13: 0 | AI13: 0 | AJ13: 0 | AK13: 0 | AL13: 0 | AM13: 0 | AN13: 0 | AO13: 0 | AP13: 0 | AQ13: 0 | AR13: 0 | AS13: 0 | AT13: 0 | AU13: 0
A14: Demarest | B14: Bergen | C14: 3400317530 | D14: borough | E14: unvisited | F14: 0 | G14: 0 | H14: 0 | I14: 0 | J14: 0 | K14: https://en.wikipedia.org/wiki/Demarest,_New_Jersey | L14: 0 | M14: 0 | N14: 0 | O14: 0 | P14: 0 | Q14: 0 | R14: 0 | S14: 0 | T14: 0 | U14: 0 | V14: 0 | W14: 0 | X14: 0 | Y14: 0 | Z14: 0 | AA14: 0 | AB14: 0 | AC14: 0 | AD14: 0 | AE14: 0 | AF14: 0 | AG14: 0 | AH14: 0 | AI14: 0 | AJ14: 0 | AK14: 0 | AL14: 0 | AM14: 0 | AN14: 0 | AO14: 0 | AP14: 0 | AQ14: 0 | AR14: 0 | AS14: 0 | AT14: 0 | AU14: 0
A15: Dumont | B15: Bergen | C15: 3400318400 | D15: borough | E15: unvisited | F15: 0 | G15: 0 | H15: 0 | I15: 0 | J15: 0 | K15: https://en.wikipedia.org/wiki/Dumont,_New_Jersey | L15: 0 | M15: 0 | N15: 0 | O15: 0 | P15: 0 | Q15: 0 | R15: 0 | S15: 0 | T15: 0 | U15: 0 | V15: 0 | W15: 0 | X15: 0 | Y15: 0 | Z15: 0 | AA15: 0 | AB15: 0 | AC15: 0 | AD15: 0 | AE15: 0 | AF15: 0 | AG15: 0 | AH15: 0 | AI15: 0 | AJ15: 0 | AK15: 0 | AL15: 0 | AM15: 0 | AN15: 0 | AO15: 0 | AP15: 0 | AQ15: 0 | AR15: 0 | AS15: 0 | AT15: 0 | AU15: 0
A16: East Rutherford | B16: Bergen | C16: 3400319510 | D16: borough | E16: visited | F16: 111 | G16: "Wawa Picnic" - Tailgating for Springsteen | H16: 2023-09-03 | I16: 0 | J16: 0 | K16: https://en.wikipedia.org/wiki/East_Rutherford,_New_Jersey | L16: NJ Town #111: East Rutherford | M16: https://www.instagram.com/p/DIuAH24xYCm/ | N16: 0 | O16: 0 | P16: 0 | Q16: 0 | R16: 0 | S16: 0 | T16: 0 | U16: 0 | V16: 0 | W16: 0 | X16: 0 | Y16: 0 | Z16: 0 | AA16: 0 | AB16: 0 | AC16: 0 | AD16: 0 | AE16: 0 | AF16: 0 | AG16: 0 | AH16: 0 | AI16: 0 | AJ16: 0 | AK16: 0 | AL16: Town #111 | AM16: https://www.instagram.com/p/DIuAH24xYCm/ | AN16: 0 | AO16: 0 | AP16: 0 | AQ16: 0 | AR16: 0 | AS16: 0 | AT16: 0 | AU16: 0
A17: Edgewater | B17: Bergen | C17: 3400320020 | D17: borough | E17: unvisited | F17: 0 | G17: 0 | H17: 0 | I17: 0 | J17: 0 | K17: https://en.wikipedia.org/wiki/Edgewater,_New_Jersey | L17: 0 | M17: 0 | N17: 0 | O17: 0 | P17: 0 | Q17: 0 | R17: 0 | S17: 0 | T17: 0 | U17: 0 | V17: 0 | W17: 0 | X17: 0 | Y17: 0 | Z17: 0 | AA17: 0 | AB17: 0 | AC17: 0 | AD17: 0 | AE17: 0 | AF17: 0 | AG17: 0 | AH17: 0 | AI17: 0 | AJ17: 0 | AK17: 0 | AL17: 0 | AM17: 0 | AN17: 0 | AO17: 0 | AP17: 0 | AQ17: 0 | AR17: 0 | AS17: 0 | AT17: 0 | AU17: 0
A18: Elmwood Park | B18: Bergen | C18: 3400321300 | D18: borough | E18: unvisited | F18: 0 | G18: 0 | H18: 0 | I18: 0 | J18: 0 | K18: https://en.wikipedia.org/wiki/Elmwood_Park,_New_Jersey | L18: 0 | M18: 0 | N18: 0 | O18: 0 | P18: 0 | Q18: 0 | R18: 0 | S18: 0 | T18: 0 | U18: 0 | V18: 0 | W18: 0 | X18: 0 | Y18: 0 | Z18: 0 | AA18: 0 | AB18: 0 | AC18: 0 | AD18: 0 | AE18: 0 | AF18: 0 | AG18: 0 | AH18: 0 | AI18: 0 | AJ18: 0 | AK18: 0 | AL18: 0 | AM18: 0 | AN18: 0 | AO18: 0 | AP18: 0 | AQ18: 0 | AR18: 0 | AS18: 0 | AT18: 0 | AU18: 0
A19: Emerson | B19: Bergen | C19: 3400321450 | D19: borough | E19: unvisited | F19: 0 | G19: 0 | H19: 0 | I19: 0 | J19: 0 | K19: https://en.wikipedia.org/wiki/Emerson,_New_Jersey | L19: 0 | M19: 0 | N19: 0 | O19: 0 | P19: 0 | Q19: 0 | R19: 0 | S19: 0 | T19: 0 | U19: 0 | V19: 0 | W19: 0 | X19: 0 | Y19: 0 | Z19: 0 | AA19: 0 | AB19: 0 | AC19: 0 | AD19: 0 | AE19: 0 | AF19: 0 | AG19: 0 | AH19: 0 | AI19: 0 | AJ19: 0 | AK19: 0 | AL19: 0 | AM19: 0 | AN19: 0 | AO19: 0 | AP19: 0 | AQ19: 0 | AR19: 0 | AS19: 0 | AT19: 0 | AU19: 0
A20: Englewood | B20: Bergen | C20: 3400321480 | D20: city | E20: unvisited | F20: 0 | G20: 0 | H20: 0 | I20: 0 | J20: 0 | K20: https://en.wikipedia.org/wiki/Englewood,_New_Jersey | L20: 0 | M20: 0 | N20: 0 | O20: 0 | P20: 0 | Q20: 0 | R20: 0 | S20: 0 | T20: 0 | U20: 0 | V20: 0 | W20: 0 | X20: 0 | Y20: 0 | Z20: 0 | AA20: 0 | AB20: 0 | AC20: 0 | AD20: 0 | AE20: 0 | AF20: 0 | AG20: 0 | AH20: 0 | AI20: 0 | AJ20: 0 | AK20: 0 | AL20: 0 | AM20: 0 | AN20: 0 | AO20: 0 | AP20: 0 | AQ20: 0 | AR20: 0 | AS20: 0 | AT20: 0 | AU20: 0
A21: Englewood Cliffs | B21: Bergen | C21: 3400321510 | D21: borough | E21: queued | F21: 167 | G21: Brownstone Pancake Factory | H21: 2024-01-15 | I21: Brownstone Pancake Factory | J21: https://www.brownstonepancakefactory.com/ | K21: https://en.wikipedia.org/wiki/Englewood_Cliffs,_New_Jersey | L21: 0 | M21: 0 | N21: 0 | O21: 0 | P21: 0 | Q21: 0 | R21: 0 | S21: 0 | T21: 0 | U21: 0 | V21: 0 | W21: 0 | X21: 0 | Y21: 0 | Z21: 0 | AA21: 0 | AB21: 0 | AC21: 0 | AD21: 0 | AE21: 0 | AF21: 0 | AG21: 0 | AH21: 0 | AI21: 0 | AJ21: 0 | AK21: 0 | AL21: 0 | AM21: 0 | AN21: 0 | AO21: 0 | AP21: 0 | AQ21: 0 | AR21: 0 | AS21: 0 | AT21: 0 | AU21: 0
A22: Fair Lawn | B22: Bergen | C22: 3400322470 | D22: borough | E22: unvisited | F22: 0 | G22: 0 | H22: 0 | I22: 0 | J22: 0 | K22: https://en.wikipedia.org/wiki/Fair_Lawn,_New_Jersey | L22: 0 | M22: 0 | N22: 0 | O22: 0 | P22: 0 | Q22: 0 | R22: 0 | S22: 0 | T22: 0 | U22: 0 | V22: 0 | W22: 0 | X22: 0 | Y22: 0 | Z22: 0 | AA22: 0 | AB22: 0 | AC22: 0 | AD22: 0 | AE22: 0 | AF22: 0 | AG22: 0 | AH22: 0 | AI22: 0 | AJ22: 0 | AK22: 0 | AL22: 0 | AM22: 0 | AN22: 0 | AO22: 0 | AP22: 0 | AQ22: 0 | AR22: 0 | AS22: 0 | AT22: 0 | AU22: 0
A23: Fairview | B23: Bergen | C23: 3400322560 | D23: borough | E23: queued | F23: 258 | G23: Cast Iron Pot Original | H23: 2024-12-30 | I23: Cast Iron Pot | J23: https://castironpotbbq.com/ | K23: https://en.wikipedia.org/wiki/Fairview,_New_Jersey | L23: 0 | M23: 0 | N23: 0 | O23: 0 | P23: 0 | Q23: 0 | R23: 0 | S23: 0 | T23: 0 | U23: 0 | V23: 0 | W23: 0 | X23: 0 | Y23: 0 | Z23: 0 | AA23: 0 | AB23: 0 | AC23: 0 | AD23: 0 | AE23: 0 | AF23: 0 | AG23: 0 | AH23: 0 | AI23: 0 | AJ23: 0 | AK23: 0 | AL23: 0 | AM23: 0 | AN23: 0 | AO23: 0 | AP23: 0 | AQ23: 0 | AR23: 0 | AS23: 0 | AT23: 0 | AU23: 0
A24: Fort Lee | B24: Bergen | C24: 3400324420 | D24: borough | E24: queued | F24: 178 | G24: Q Grill Korean BBQ & Seafood | H24: 2024-02-17 | I24: Q Grill | J24: https://qgrillkbbq.com/ | K24: https://en.wikipedia.org/wiki/Fort_Lee,_New_Jersey | L24: 0 | M24: 0 | N24: 0 | O24: 0 | P24: 0 | Q24: 0 | R24: 0 | S24: 0 | T24: 0 | U24: 0 | V24: 0 | W24: 0 | X24: 0 | Y24: 0 | Z24: 0 | AA24: 0 | AB24: 0 | AC24: 0 | AD24: 0 | AE24: 0 | AF24: 0 | AG24: 0 | AH24: 0 | AI24: 0 | AJ24: 0 | AK24: 0 | AL24: 0 | AM24: 0 | AN24: 0 | AO24: 0 | AP24: 0 | AQ24: 0 | AR24: 0 | AS24: 0 | AT24: 0 | AU24: 0
A25: Franklin Lakes | B25: Bergen | C25: 3400324990 | D25: borough | E25: unvisited | F25: 0 | G25: 0 | H25: 0 | I25: 0 | J25: 0 | K25: https://en.wikipedia.org/wiki/Franklin_Lakes,_New_Jersey | L25: 0 | M25: 0 | N25: 0 | O25: 0 | P25: 0 | Q25: 0 | R25: 0 | S25: 0 | T25: 0 | U25: 0 | V25: 0 | W25: 0 | X25: 0 | Y25: 0 | Z25: 0 | AA25: 0 | AB25: 0 | AC25: 0 | AD25: 0 | AE25: 0 | AF25: 0 | AG25: 0 | AH25: 0 | AI25: 0 | AJ25: 0 | AK25: 0 | AL25: 0 | AM25: 0 | AN25: 0 | AO25: 0 | AP25: 0 | AQ25: 0 | AR25: 0 | AS25: 0 | AT25: 0 | AU25: 0
A26: Garfield | B26: Bergen | C26: 3400325770 | D26: city | E26: unvisited | F26: 0 | G26: 0 | H26: 0 | I26: 0 | J26: 0 | K26: https://en.wikipedia.org/wiki/Garfield,_New_Jersey | L26: 0 | M26: 0 | N26: 0 | O26: 0 | P26: 0 | Q26: 0 | R26: 0 | S26: 0 | T26: 0 | U26: 0 | V26: 0 | W26: 0 | X26: 0 | Y26: 0 | Z26: 0 | AA26: 0 | AB26: 0 | AC26: 0 | AD26: 0 | AE26: 0 | AF26: 0 | AG26: 0 | AH26: 0 | AI26: 0 | AJ26: 0 | AK26: 0 | AL26: 0 | AM26: 0 | AN26: 0 | AO26: 0 | AP26: 0 | AQ26: 0 | AR26: 0 | AS26: 0 | AT26: 0 | AU26: 0
A27: Glen Rock | B27: Bergen | C27: 3400326640 | D27: borough | E27: unvisited | F27: 0 | G27: 0 | H27: 0 | I27: 0 | J27: 0 | K27: https://en.wikipedia.org/wiki/Glen_Rock,_New_Jersey | L27: 0 | M27: 0 | N27: 0 | O27: 0 | P27: 0 | Q27: 0 | R27: 0 | S27: 0 | T27: 0 | U27: 0 | V27: 0 | W27: 0 | X27: 0 | Y27: 0 | Z27: 0 | AA27: 0 | AB27: 0 | AC27: 0 | AD27: 0 | AE27: 0 | AF27: 0 | AG27: 0 | AH27: 0 | AI27: 0 | AJ27: 0 | AK27: 0 | AL27: 0 | AM27: 0 | AN27: 0 | AO27: 0 | AP27: 0 | AQ27: 0 | AR27: 0 | AS27: 0 | AT27: 0 | AU27: 0
A28: Hackensack | B28: Bergen | C28: 3400328680 | D28: city | E28: queued | F28: 233 | G28: White Manna Hamburgers | H28: 2024-09-21 | I28: White Manna | J28: https://www.whitemanna.com/ | K28: https://en.wikipedia.org/wiki/Hackensack,_New_Jersey | L28: 0 | M28: 0 | N28: 0 | O28: 0 | P28: 0 | Q28: 0 | R28: 0 | S28: 0 | T28: 0 | U28: 0 | V28: 0 | W28: 0 | X28: 0 | Y28: 0 | Z28: 0 | AA28: 0 | AB28: 0 | AC28: 0 | AD28: 0 | AE28: 0 | AF28: 0 | AG28: 0 | AH28: 0 | AI28: 0 | AJ28: 0 | AK28: 0 | AL28: 0 | AM28: 0 | AN28: 0 | AO28: 0 | AP28: 0 | AQ28: 0 | AR28: 0 | AS28: 0 | AT28: 0 | AU28: 0
A29: Harrington Park | B29: Bergen | C29: 3400330150 | D29: borough | E29: unvisited | F29: 0 | G29: 0 | H29: 0 | I29: 0 | J29: 0 | K29: https://en.wikipedia.org/wiki/Harrington_Park,_New_Jersey | L29: 0 | M29: 0 | N29: 0 | O29: 0 | P29: 0 | Q29: 0 | R29: 0 | S29: 0 | T29: 0 | U29: 0 | V29: 0 | W29: 0 | X29: 0 | Y29: 0 | Z29: 0 | AA29: 0 | AB29: 0 | AC29: 0 | AD29: 0 | AE29: 0 | AF29: 0 | AG29: 0 | AH29: 0 | AI29: 0 | AJ29: 0 | AK29: 0 | AL29: 0 | AM29: 0 | AN29: 0 | AO29: 0 | AP29: 0 | AQ29: 0 | AR29: 0 | AS29: 0 | AT29: 0 | AU29: 0
A30: Hasbrouck Heights | B30: Bergen | C30: 3400330420 | D30: borough | E30: unvisited | F30: 0 | G30: 0 | H30: 0 | I30: 0 | J30: 0 | K30: https://en.wikipedia.org/wiki/Hasbrouck_Heights,_New_Jersey | L30: 0 | M30: 0 | N30: 0 | O30: 0 | P30: 0 | Q30: 0 | R30: 0 | S30: 0 | T30: 0 | U30: 0 | V30: 0 | W30: 0 | X30: 0 | Y30: 0 | Z30: 0 | AA30: 0 | AB30: 0 | AC30: 0 | AD30: 0 | AE30: 0 | AF30: 0 | AG30: 0 | AH30: 0 | AI30: 0 | AJ30: 0 | AK30: 0 | AL30: 0 | AM30: 0 | AN30: 0 | AO30: 0 | AP30: 0 | AQ30: 0 | AR30: 0 | AS30: 0 | AT30: 0 | AU30: 0
A31: Haworth | B31: Bergen | C31: 3400330540 | D31: borough | E31: unvisited | F31: 0 | G31: 0 | H31: 0 | I31: 0 | J31: 0 | K31: https://en.wikipedia.org/wiki/Haworth,_New_Jersey | L31: 0 | M31: 0 | N31: 0 | O31: 0 | P31: 0 | Q31: 0 | R31: 0 | S31: 0 | T31: 0 | U31: 0 | V31: 0 | W31: 0 | X31: 0 | Y31: 0 | Z31: 0 | AA31: 0 | AB31: 0 | AC31: 0 | AD31: 0 | AE31: 0 | AF31: 0 | AG31: 0 | AH31: 0 | AI31: 0 | AJ31: 0 | AK31: 0 | AL31: 0 | AM31: 0 | AN31: 0 | AO31: 0 | AP31: 0 | AQ31: 0 | AR31: 0 | AS31: 0 | AT31: 0 | AU31: 0
A32: Hillsdale | B32: Bergen | C32: 3400331920 | D32: borough | E32: unvisited | F32: 0 | G32: 0 | H32: 0 | I32: 0 | J32: 0 | K32: https://en.wikipedia.org/wiki/Hillsdale,_New_Jersey | L32: 0 | M32: 0 | N32: 0 | O32: 0 | P32: 0 | Q32: 0 | R32: 0 | S32: 0 | T32: 0 | U32: 0 | V32: 0 | W32: 0 | X32: 0 | Y32: 0 | Z32: 0 | AA32: 0 | AB32: 0 | AC32: 0 | AD32: 0 | AE32: 0 | AF32: 0 | AG32: 0 | AH32: 0 | AI32: 0 | AJ32: 0 | AK32: 0 | AL32: 0 | AM32: 0 | AN32: 0 | AO32: 0 | AP32: 0 | AQ32: 0 | AR32: 0 | AS32: 0 | AT32: 0 | AU32: 0
A33: Ho-Ho-Kus | B33: Bergen | C33: 3400332310 | D33: borough | E33: unvisited | F33: 0 | G33: 0 | H33: 0 | I33: 0 | J33: 0 | K33: https://en.wikipedia.org/wiki/Ho-Ho-Kus,_New_Jersey | L33: 0 | M33: 0 | N33: 0 | O33: 0 | P33: 0 | Q33: 0 | R33: 0 | S33: 0 | T33: 0 | U33: 0 | V33: 0 | W33: 0 | X33: 0 | Y33: 0 | Z33: 0 | AA33: 0 | AB33: 0 | AC33: 0 | AD33: 0 | AE33: 0 | AF33: 0 | AG33: 0 | AH33: 0 | AI33: 0 | AJ33: 0 | AK33: 0 | AL33: 0 | AM33: 0 | AN33: 0 | AO33: 0 | AP33: 0 | AQ33: 0 | AR33: 0 | AS33: 0 | AT33: 0 | AU33: 0
A34: Leonia | B34: Bergen | C34: 3400340020 | D34: borough | E34: unvisited | F34: 0 | G34: 0 | H34: 0 | I34: 0 | J34: 0 | K34: https://en.wikipedia.org/wiki/Leonia,_New_Jersey | L34: 0 | M34: 0 | N34: 0 | O34: 0 | P34: 0 | Q34: 0 | R34: 0 | S34: 0 | T34: 0 | U34: 0 | V34: 0 | W34: 0 | X34: 0 | Y34: 0 | Z34: 0 | AA34: 0 | AB34: 0 | AC34: 0 | AD34: 0 | AE34: 0 | AF34: 0 | AG34: 0 | AH34: 0 | AI34: 0 | AJ34: 0 | AK34: 0 | AL34: 0 | AM34: 0 | AN34: 0 | AO34: 0 | AP34: 0 | AQ34: 0 | AR34: 0 | AS34: 0 | AT34: 0 | AU34: 0
A35: Little Ferry | B35: Bergen | C35: 3400340680 | D35: borough | E35: unvisited | F35: 0 | G35: 0 | H35: 0 | I35: 0 | J35: 0 | K35: https://en.wikipedia.org/wiki/Little_Ferry,_New_Jersey | L35: 0 | M35: 0 | N35: 0 | O35: 0 | P35: 0 | Q35: 0 | R35: 0 | S35: 0 | T35: 0 | U35: 0 | V35: 0 | W35: 0 | X35: 0 | Y35: 0 | Z35: 0 | AA35: 0 | AB35: 0 | AC35: 0 | AD35: 0 | AE35: 0 | AF35: 0 | AG35: 0 | AH35: 0 | AI35: 0 | AJ35: 0 | AK35: 0 | AL35: 0 | AM35: 0 | AN35: 0 | AO35: 0 | AP35: 0 | AQ35: 0 | AR35: 0 | AS35: 0 | AT35: 0 | AU35: 0
A36: Lodi | B36: Bergen | C36: 3400341100 | D36: borough | E36: pre-challenge | F36: 0 | G36: Wawa | H36: 2022-10-10 | I36: 0 | J36: 0 | K36: https://en.wikipedia.org/wiki/Lodi,_New_Jersey | L36: 0 | M36: 0 | N36: 0 | O36: 0 | P36: 0 | Q36: 0 | R36: 0 | S36: 0 | T36: 0 | U36: 0 | V36: 0 | W36: 0 | X36: 0 | Y36: 0 | Z36: 0 | AA36: 0 | AB36: 0 | AC36: 0 | AD36: 0 | AE36: 0 | AF36: 0 | AG36: 0 | AH36: 0 | AI36: 0 | AJ36: 0 | AK36: 0 | AL36: 0 | AM36: 0 | AN36: 0 | AO36: 0 | AP36: 0 | AQ36: 0 | AR36: 0 | AS36: 0 | AT36: 0 | AU36: 0
A37: Lyndhurst | B37: Bergen | C37: 3400342090 | D37: township | E37: pre-challenge | F37: 0 | G37: Lassoni | H37: 2016-11-19 | I37: Lassoni Restaurant | J37: https://lassonirestaurant.com/ | K37: https://en.wikipedia.org/wiki/Lyndhurst_Township,_New_Jersey | L37: 0 | M37: 0 | N37: 0 | O37: 0 | P37: 0 | Q37: 0 | R37: 0 | S37: 0 | T37: 0 | U37: 0 | V37: 0 | W37: 0 | X37: 0 | Y37: 0 | Z37: 0 | AA37: 0 | AB37: 0 | AC37: 0 | AD37: 0 | AE37: 0 | AF37: 0 | AG37: 0 | AH37: 0 | AI37: 0 | AJ37: 0 | AK37: 0 | AL37: 0 | AM37: 0 | AN37: 0 | AO37: 0 | AP37: 0 | AQ37: 0 | AR37: 0 | AS37: 0 | AT37: 0 | AU37: 0
A38: Mahwah | B38: Bergen | C38: 3400342750 | D38: township | E38: queued | F38: 213 | G38: Prime No. 7 x Ugly Chicken Korean BBQ | H38: 2024-07-12 | I38: Prime No.7 | J38: https://primeno7.com/ | K38: https://en.wikipedia.org/wiki/Mahwah_Township,_New_Jersey | L38: 0 | M38: 0 | N38: 0 | O38: 0 | P38: 0 | Q38: 0 | R38: 0 | S38: 0 | T38: 0 | U38: 0 | V38: 0 | W38: 0 | X38: 0 | Y38: 0 | Z38: 0 | AA38: 0 | AB38: 0 | AC38: 0 | AD38: 0 | AE38: 0 | AF38: 0 | AG38: 0 | AH38: 0 | AI38: 0 | AJ38: 0 | AK38: 0 | AL38: 0 | AM38: 0 | AN38: 0 | AO38: 0 | AP38: 0 | AQ38: 0 | AR38: 0 | AS38: 0 | AT38: 0 | AU38: 0
A39: Maywood | B39: Bergen | C39: 3400344880 | D39: borough | E39: pre-challenge | F39: 0 | G39: Mario's Pizza | H39: 2021-12-03 | I39: Mario's Pizza | J39: https://www.mariospizzanj.com/ | K39: https://en.wikipedia.org/wiki/Maywood,_New_Jersey | L39: 0 | M39: 0 | N39: 0 | O39: 0 | P39: 0 | Q39: 0 | R39: 0 | S39: 0 | T39: 0 | U39: 0 | V39: 0 | W39: 0 | X39: 0 | Y39: 0 | Z39: 0 | AA39: 0 | AB39: 0 | AC39: 0 | AD39: 0 | AE39: 0 | AF39: 0 | AG39: 0 | AH39: 0 | AI39: 0 | AJ39: 0 | AK39: 0 | AL39: 0 | AM39: 0 | AN39: 0 | AO39: 0 | AP39: 0 | AQ39: 0 | AR39: 0 | AS39: 0 | AT39: 0 | AU39: 0
A40: Midland Park | B40: Bergen | C40: 3400346110 | D40: borough | E40: unvisited | F40: 0 | G40: 0 | H40: 0 | I40: 0 | J40: 0 | K40: https://en.wikipedia.org/wiki/Midland_Park,_New_Jersey | L40: 0 | M40: 0 | N40: 0 | O40: 0 | P40: 0 | Q40: 0 | R40: 0 | S40: 0 | T40: 0 | U40: 0 | V40: 0 | W40: 0 | X40: 0 | Y40: 0 | Z40: 0 | AA40: 0 | AB40: 0 | AC40: 0 | AD40: 0 | AE40: 0 | AF40: 0 | AG40: 0 | AH40: 0 | AI40: 0 | AJ40: 0 | AK40: 0 | AL40: 0 | AM40: 0 | AN40: 0 | AO40: 0 | AP40: 0 | AQ40: 0 | AR40: 0 | AS40: 0 | AT40: 0 | AU40: 0
A41: Montvale | B41: Bergen | C41: 3400347610 | D41: borough | E41: queued | F41: 291 | G41: Fire & Oak | H41: 46251 | I41: Fire & Oak | J41: https://www.fireandoak.com/ | K41: https://en.wikipedia.org/wiki/Montvale,_New_Jersey | L41: 0 | M41: 0 | N41: 0 | O41: 0 | P41: 0 | Q41: 0 | R41: 0 | S41: 0 | T41: 0 | U41: 0 | V41: 0 | W41: 0 | X41: 0 | Y41: 0 | Z41: 0 | AA41: 0 | AB41: 0 | AC41: 0 | AD41: 0 | AE41: 0 | AF41: 0 | AG41: 0 | AH41: 0 | AI41: 0 | AJ41: 0 | AK41: 0 | AL41: 0 | AM41: 0 | AN41: 0 | AO41: 0 | AP41: 0 | AQ41: 0 | AR41: 0 | AS41: 0 | AT41: 0 | AU41: 0
...

Sheet Burlington
A1: Burlington County
A2: Total Towns | B2: =COUNTIF(Data!B$3:B$602,"Burlington") -> 40 | C2: Visited | D2: =COUNTIFS(Data!B$3:B$602,"Burlington",Data!E3:E602,"visited")+COUNTIFS(Data!B$3:B$602,"Burlington",Data!E3:E602,"queued")+COUNTIFS(Data!B$3:B$602,"Burlington",Data!E3:E602,"pre-challenge") -> 20 | E2: To Go | F2: =B2-D2 -> 20
A4: MUNICIPALITY | E4: VISIT DATA | I4: RESTAURANT LINK | K4: WIKIPEDIA | L4: INSTAGRAM | P4: TIKTOK | T4: YOUTUBE | X4: THREADS | AB4: BLUESKY | AF4: FACEBOOK | AJ4: EXTRA / OVERFLOW LINKS
A5: name | B5: county | C5: geoid | D5: townType | E5: status | F5: visitNumber | G5: restaurantName | H5: dateVisited | I5: restaurant_label | J5: restaurant_url | K5: wikipedia_url | L5: instagram1_label | M5: instagram1_url | N5: instagram2_label | O5: instagram2_url | P5: tiktok1_label | Q5: tiktok1_url | R5: tiktok2_label | S5: tiktok2_url | T5: youtube1_label | U5: youtube1_url | V5: youtube2_label | W5: youtube2_url | X5: threads1_label | Y5: threads1_url | Z5: threads2_label | AA5: threads2_url | AB5: bluesky1_label | AC5: bluesky1_url | AD5: bluesky2_label | AE5: bluesky2_url | AF5: facebook1_label | AG5: facebook1_url | AH5: facebook2_label | AI5: facebook2_url | AJ5: extra1_category | AK5: extra1_platform | AL5: extra1_label | AM5: extra1_url | AN5: extra2_category | AO5: extra2_platform | AP5: extra2_label | AQ5: extra2_url | AR5: extra3_category | AS5: extra3_platform | AT5: extra3_label | AU5: extra3_url
A6: {=_xlfn._xlws.FILTER(Data!A$3:AU$602,Data!B$3:B$602="Burlington","")} -> Bass River | B6: Burlington | C6: 3400503370 | D6: township | E6: queued | F6: 224 | G6: Sad Boyz | H6: 45529 | I6: Sad Boyz | J6: https://sadboyzbites.com/ | K6: https://en.wikipedia.org/wiki/Bass_River_Township,_New_Jersey | L6: 0 | M6: 0 | N6: 0 | O6: 0 | P6: 0 | Q6: 0 | R6: 0 | S6: 0 | T6: 0 | U6: 0 | V6: 0 | W6: 0 | X6: 0 | Y6: 0 | Z6: 0 | AA6: 0 | AB6: 0 | AC6: 0 | AD6: 0 | AE6: 0 | AF6: 0 | AG6: 0 | AH6: 0 | AI6: 0 | AJ6: 0 | AK6: 0 | AL6: 0 | AM6: 0 | AN6: 0 | AO6: 0 | AP6: 0 | AQ6: 0 | AR6: 0 | AS6: 0 | AT6: 0 | AU6: 0
